Workbook
Name Burgers: Menu!$I$5:$I$14
Name Fries: Menu!$I$35:$I$37
Name Light: Menu!$I$38:$I$41
Name Pizzas: Menu!$I$15:$I$19
Name Rolls: Menu!$I$20:$I$26
Name Starters: Menu!$I$27:$I$34

Sheet Menu
G2: Menu
H3: Category | I3: Item Name | J3: Price (Rs) | K3: Details
H5: Burgers | I5: Classic Beef | J5: 450 | K5: Traditional juicy beef patty with classic toppings.
H6: Burgers | I6: Mighty Burger | J6: 460 | K6: A large, filling burger for a hearty appetite.
H7: Burgers | I7: Zinger Burger | J7: 340 | K7: Crispy fried chicken fillet with a signature spicy kick.
H8: Burgers | I8: Juicy Burger | J8: 500 | K8: Extra succulent patty with premium sauces.
H9: Burgers | I9: BBQ Chicken Burger | J9: 450 | K9: Grilled chicken smothered in smoky BBQ sauce.
H10: Burgers | I10: Food Junction Special | J10: 550 | K10: The chef's signature burger with exclusive ingredients.
H11: Burgers | I11: Paneer Tikka Burger | J11: 420 | K11: Vegetarian delight featuring spiced paneer cubes.
H12: Burgers | I12: Double Patty Chicken | J12: 500 | K12: Two crispy chicken patties for double the flavor.
H13: Burgers | I13: Melt Master Burger | J13: 550 | K13: Loaded with extra melted cheese and premium toppings.
H14: Burgers | I14: Spice Blast Burger | J14: 450 | K14: For spice lovers, packed with hot peppers and sauce.
H15: Pizzas | I15: Chicken Fajita (S/M/L) | J15: 650 / 1050 / 1650 | K15: Topped with fajita chicken, onions, and bell peppers.
H16: Pizzas | I16: Chicken Tikka (S/M/L) | J16: 650 / 1050 / 1650 | K16: Classic local flavor with spicy chicken tikka chunks.
H17: Pizzas | I17: Malai Boti (S/M/L) | J17: 700 / 1150 / 1750 | K17: Creamy and mild chicken boti with a soft texture.
H18: Pizzas | I18: Chicken Teriyaki (S/M/L) | J18: 700 / 1150 / 1750 | K18: Exotic sweet and savory teriyaki glazed chicken.
H19: Pizzas | I19: Veggie Supreme (S/M/L) | J19: 600 / 1000 / 1550 | K19: Loaded with fresh garden vegetables and olives.
H20: Rolls & Wraps | I20: Ro | J20: 300 | K20: Succulent chicken chunks wrapped with creamy mayo.
H21: Rolls & Wraps | I21: Twister Roll | J21: 300 | K21: Crispy chicken strips with fresh salad in a soft wrap.
H22: Rolls & Wraps | I22: Beef Kabab Roll | J22: 400 | K22: Traditional seekh kabab wrapped in a paratha/tortilla.
H23: Rolls & Wraps | I23: Grilled Wrap | J23: 400 | K23: Healthy grilled chicken with fresh veggies.
H24: Rolls & Wraps | I24: Tortilla Wrap | J24: 450 | K24: Large tortilla stuffed with premium fillings.
H25: Rolls & Wraps | I25: Chicken Shawarma Wrap | J25: 280 | K25: Authentic thinly sliced chicken with garlic sauce.
H26: Rolls & Wraps | I26: Veggie Delight Wrap | J26: 300 | K26: A fresh mix of sautéed and raw vegetables.
H27: Starters | I27: trs | J27: 500 | K27: Golden fried chicken nuggets.
H28: Starters | I28: Hot Wings (10 pcs) | J28: 580 | K28: Spicy breaded wings served hot.
H29: Starters | I29: Honey Wings (10 pcs) | J29: 550 | K29: Sweet and tangy glazed chicken wings.
H30: Starters | I30: Tuna Pasta | J30: 600 | K30: Cold/Hot pasta tossed with premium tuna.
H31: Starters | I31: Cheese Pasta | J31: 600 | K31: Rich, creamy pasta loaded with melted cheese.
... H41: Light Veg | I41: Fruit Chaat | J41: 180 | K41: Fresh seasonal fruits with local spices.
E259: Classic Beef
E260: Mighty Burger
E261: Zinger Burger | G261: Burgers
E262: Juicy Burger | G262: Pizzas
E263: BBQ Chicken Burger | G263: Rolls & Wraps
E264: Food Junction Special | G264: Starters
E265: Paneer Tikka Burger | G265: Fries
E266: Double Patty Chicken | G266: Light Veg
E267: Melt Master Burger | G267: Combo Deal
E268: Spice Blast Burger
...

Sheet Deals
F3: Deals
G5: Category | H5: Item Name | I5: Price (Rs.) | J5: Description / Includes
G6: Combo Deal | H6: Family Pizza Pack | I6: 1700 | J6: 2 Medium Pizzas + 1L Drink + Regular Fries
G7: Combo Deal | H7: The Burger Feast | I7: 1800 | J7: 5 Zinger Burgers + 2L Drink + 2 Fries
G8: Combo Deal | H8: Urban Feast Deal | I8: 600 | J8: 1 Mighty Burger + 1 Plain Fries + 1 Reg Drink
G9: Combo Deal | H9: Chicken Crunch Deal | I9: 2200 | J9: 10 Nuggets + 10 Hotwings + 10 Honey wings + 1.5L Drink + 2 Fries
G10: Combo Deal | H10: Pizza Lover's Delight | I10: 1800 | J10: Chicken Fajita (M) + Chicken Tikka (M) + Regular Fries
G11: Combo Deal | H11: Roll & Wrap Special | I11: 1100 | J11: Chicken Mayo Roll + Beef Kabab Roll + Tortilla Wrap + Veggie Delight Wrap
G12: Combo Deal | H12: Starter Explosion | I12: 1000 | J12: Nuggets (10 pcs) + Hot Wings (10 pcs) + Crispy Onion Rings
G13: Combo Deal | H13: Veggie Feast Deal | I13: 2200 | J13: Veggie Supreme (L) + Paneer Tikka Burger + Loaded Fries + Garden Salad

Sheet Orders
F2: ORDERS
G5: Column1 | H5: Column1 | I5: Column2 | J5: Column3 | K5: Column4 | L5: Column5 | M5: Column6
G6: Order # | H6: Customer Name | I6: Item 1 | J6: Category | K6: Qty | L6: Price | M6: Item 2 | N6: Category | O6: Qty | P6: Price | Q6: Grand Total (Rs.)
G7: 1 | H7: Ahmed Mansoor | I7: Chicken Crunch Deal | J7: Combo Deal | K7: 2 | L7: 1800 | M7: Pizza Fries | N7: Fries | O7: 1 | P7: 560 | Q7: =Table1[[#This Row],[Column4]]*Table1[[#This Row],[Column5]] -> 3600
G8: 2 | H8: Sara Siddiqui | I8: Food Junction Special | J8: Rolls & Wraps | K8: 1 | L8: 1050 | M8: Starter Explosion | N8: Combo | O8: 1 | P8: 1000 | Q8: =Table1[[#This Row],[Column4]]*Table1[[#This Row],[Column5]]+O8*P8 -> 2050
G9: 3 | H9: Bilal Khan | I9: Mighty Burger | J9: Burgers | K9: 2 | L9: 920 | M9: Urban Feast Deal | N9: Combo | O9: 1 | P9: 600 | Q9: =Table1[[#This Row],[Column4]]*Table1[[#This Row],[Column5]]+O9*P9 -> 2440
G10: 4 | H10: Fatima Zahra | I10: Family Pizza Pack | J10: Combo | K10: 1 | L10: 1700 | M10: Russian Salad | N10: Starters | O10: 2 | P10: 800 | Q10: =Table1[[#This Row],[Column4]]*Table1[[#This Row],[Column5]]+O10*P10 -> 3300
G11: 5 | H11: Zaid Ali | I11: Chicken Crunch Deal | J11: Combo | K11: 1 | L11: 2200 | M11: Zinger Burger | N11: Burgers | O11: 1 | P11: 340 | Q11: =Table1[[#This Row],[Column4]]*Table1[[#This Row],[Column5]]+O11*P11 -> 2540
G12: 6 | H12: Mariam Jameel | I12: Pizza Lover's Delight | J12: Combo | K12: 1 | L12: 1800 | M12: Hot Wings (10pcs) | N12: Starters | O12: 1 | P12: 580 | Q12: =Table1[[#This Row],[Column4]]*Table1[[#This Row],[Column5]]+O12*P12 -> 2380
G13: 7 | H13: Hamza Sheikh | I13: Roll & Wrap Special | J13: Combo | K13: 1 | L13: 1100 | M13: Loaded Fries | N13: Fries | O13: 2 | P13: 900 | Q13: =Table1[[#This Row],[Column4]]*Table1[[#This Row],[Column5]]+O13*P13 -> 2900
G14: 8 | H14: Aisha Noor | I14: Veggie Feast Deal | J14: Combo | K14: 1 | L14: 2200 | M14: Fresh Garden Salad | N14: Light Veg | O14: 1 | P14: 350 | Q14: =Table1[[#This Row],[Column4]]*Table1[[#This Row],[Column5]]+O14*P14 -> 2550
G15: 9 | H15: Usman Ghani | I15: Juicy Burger | J15: Burgers | K15: 2 | L15: 1000 | M15: Urban Feast Deal | N15: Combo | O15: 2 | P15: 1200 | Q15: =Table1[[#This Row],[Column4]]*Table1[[#This Row],[Column5]]+O15*P15 -> 4400
G16: 10 | H16: Hina Malik | I16: Malai Boti (L) | J16: Pizzas | K16: 1 | L16: 1750 | M16: Starter Explosion | N16: Combo | O16: 1 | P16: 1000 | Q16: =Table1[[#This Row],[Column4]]*Table1[[#This Row],[Column5]]+O16*P16 -> 2750
G17: 11 | H17: Omer Farooq | I17: The Burger Feast | J17: Combo | K17: 1 | L17: 1800 | M17: Dynamite Chicken | N17: Starters | O17: 1 | P17: 600 | Q17: =Table1[[#This Row],[Column4]]*Table1[[#This Row],[Column5]]+O17*P17 -> 2400
G18: 12 | H18: Sana Tariq | I18: Cheese Pasta | J18: Starters | K18: 2 | L18: 1200 | M18: Twister Roll | N18: Rolls | O18: 2 | P18: 600 | Q18: =Table1[[#This Row],[Column4]]*Table1[[#This Row],[Column5]]+O18*P18 -> 3600
G19: 13 | H19: Zainab Bibi | I19: Family Pizza Pack | J19: Combo | K19: 1 | L19: 1700 | M19: Honey Wings (10pcs) | N19: Starters | O19: 1 | P19: 550 | Q19: =Table1[[#This Row],[Column4]]*Table1[[#This Row],[Column5]]+O19*P19 -> 2250
... G35: 29 | H35: Eshal Fatima | I35: Malai Boti (S) | J35: Pizzas | K35: 2 | L35: 1400 | M35: Roll & Wrap Special | N35: Combo | O35: 1 | P35: 1100 | Q35: =Table1[[#This Row],[Column4]]*Table1[[#This Row],[Column5]]+O35*P35 -> 3900
G36: 30 | H36: Raza Abidi | I36: The Burger Feast | J36: Combo | K36: 1 | L36: 1800 | M36: Pizza Fries | N36: Fries | O36: 1 | P36: 560 | Q36: =K36*L36+O36*P36 -> 2360

Sheet Pizza
D2: Pizza
E4: Item name | F4: Total quantity | G4: Unit Price RS-/ | H4: Total Sum
E5: Item Name | F5: Total Quantity | G5: Unit Price (Rs.) | H5: Total Sum (Rs.)
E6: Malai Boti (L) | F6: 2 | G6: 1750 | H6: =Table3[[#This Row],[Total quantity]]*Table3[[#This Row],[Unit Price RS-/]] -> 3500
E7: Malai Boti (S) | F7: 3 | G7: 700 | H7: =Table3[[#This Row],[Total quantity]]*Table3[[#This Row],[Unit Price RS-/]] -> 2100
E8: Chicken Tikka (S) | F8: 2 | G8: 650 | H8: =Table3[[#This Row],[Total quantity]]*Table3[[#This Row],[Unit Price RS-/]] -> 1300
E9: Chicken Fajita (M) | F9: 1 | G9: 1050 | H9: =Table3[[#This Row],[Total quantity]]*Table3[[#This Row],[Unit Price RS-/]] -> 1050
E10: Chicken Teriyaki (M) | F10: 1 | G10: 1150 | H10: =Table3[[#This Row],[Total quantity]]*Table3[[#This Row],[Unit Price RS-/]] -> 1150
E11: Chicken Fajita (L) | F11: 1 | G11: 1650 | H11: =Table3[[#This Row],[Total quantity]]*Table3[[#This Row],[Unit Price RS-/]] -> 1650
E12: Total Pizzas | F12: =SUM(F6:F11) -> 10 | H12: =SUM(H6:H11) -> 10750

Sheet Rolls and Warps
B1: Rolls & Wraps
C3: Item name | D3: Total quantity | E3: Unit Price RS-/ | F3: Total Sum
C4: Item Name | D4: Total Quantity | E4: Unit Price (Rs.) | F4: Total Sum (Rs.)
C5: Chicken Mayo Roll | D5: 5 | E5: 300 | F5: =D5*E5 -> 1500
C6: Twister Roll | D6: 6 | E6: 300 | F6: =D6*E6 -> 1800
C7: Beef Kabab Roll | D7: 3 | E7: 400 | F7: =D7*E7 -> 1200
C8: Grilled Wrap | D8: 4 | E8: 400 | F8: =D8*E8 -> 1600
C9: Tortilla Wrap | D9: 5 | E9: 450 | F9: =D9*E9 -> 2250
C10: Total | D10: =SUM(D5:D9) -> 23 | E10: — | F10: =SUM(F5:F9) -> 8350

Sheet Burgers
B1: Burgers
C4: Item name | D4: Total quantity | E4: Unit Price RS-/ | F4: Total Sum
C5: Classic Beef | D5: 2 | E5: 450 | F5: =D5*E5 -> 900
C6: Mighty Burger | D6: 3 | E6: 460 | F6: =D6*E6 -> 1380
C7: Zinger Burger | D7: 4 | E7: 340 | F7: =D7*E7 -> 1360
C8: Juicy Burger | D8: 3 | E8: 500 | F8: =D8*E8 -> 1500
C9: Food Junction Special | D9: 2 | E9: 550 | F9: =D9*E9 -> 1100
C10: Melt Master Burger | D10: 2 | E10: 550 | F10: =D10*E10 -> 1100
C11: Spice Blast Burger | D11: 2 | E11: 450 | F11: =D11*E11 -> 900
C12: Paneer Tikka Burger | D12: 1 | E12: 420 | F12: =D12*E12 -> 420
C13: TOTAL | D13: =SUM(D5:D12) -> 19 | E13: — | F13: =SUM(F5:F12) -> 8660

Sheet Starters
B2: Starters
C4: Item name | D4: Total quantity | E4: Unit Price RS-/ | F4: Total Sum
C5: Item Name | D5: Total Quantity | E5: Unit Price (Rs.) | F5: Total Sum (Rs.)
C6: Nuggets (10 pcs) | D6: 3 | E6: 500 | F6: =D6*E6 -> 1500
C7: Hot Wings (10 pcs) | D7: 6 | E7: 580 | F7: =D7*E7 -> 3480
C8: Honey Wings (10 pcs) | D8: 4 | E8: 550 | F8: =D8*E8 -> 2200
C9: Tuna Pasta | D9: 2 | E9: 600 | F9: =D9*E9 -> 1200
C10: Cheese Pasta | D10: 2 | E10: 600 | F10: =D10*E10 -> 1200
C11: Russian Salad | D11: 5 | E11: 400 | F11: =D11*E11 -> 2000
C12: Total Starters | D12: =SUM(D6:D11) -> 22 | E12: — | F12: =SUM(F6:F11) -> 11580

Sheet Light Veg
C2: Light Veg
D3: Item Name | E3: Total Quantity | F3: Unit Price (Rs.) | G3: Total Sum (Rs.)
D4: Fresh Garden Salad | E4: 4 | F4: 350 | G4: =Table5[[#This Row],[Total Quantity]]*Table5[[#This Row],[Unit Price (Rs.)]] -> 1400
D5: Anday Wala Burger | E5: 6 | F5: 220 | G5: =Table5[[#This Row],[Total Quantity]]*Table5[[#This Row],[Unit Price (Rs.)]] -> 1320
D6: Samosa Chaat | E6: 5 | F6: 180 | G6: =Table5[[#This Row],[Total Quantity]]*Table5[[#This Row],[Unit Price (Rs.)]] -> 900
D7: Fruit Chaat | E7: 5 | F7: 180 | G7: =Table5[[#This Row],[Total Quantity]]*Table5[[#This Row],[Unit Price (Rs.)]] -> 900
D8: Total Light Veg | E8: =SUM(E4:E7) -> 20 | F8: — | G8: =SUM(G4:G7) -> 4520

Sheet Fries
B2: Fries
C4: Item name | D4: Total quantity | E4: Unit Price RS-/ | F4: Total Sum
C5: Regular Fries | D5: 5 | E5: 290 | F5: =Table4[[#This Row],[Total quantity]]*Table4[[#This Row],[Unit Price RS-/]] -> 1450
C6: Loaded Fries | D6: 6 | E6: 450 | F6: =Table4[[#This Row],[Total quantity]]*Table4[[#This Row],[Unit Price RS-/]] -> 2700
C7: Pizza Fries | D7: 8 | E7: 560 | F7: =Table4[[#This Row],[Total quantity]]*Table4[[#This Row],[Unit Price RS-/]] -> 4480
C8: TOTAL | D8: =SUM(D5:D7) -> 19 | F8: =SUM(F5:F7) -> 8630

Sheet Combo Deals
D2: Combo Deals
E3: Item Name | F3: Total Quantity | G3: Unit Price (Rs.) | H3: Total Sum (Rs.)
E4: The Burger Feast | F4: 5 | G4: 1800 | H4: =F4*G4 -> 9000
E5: Urban Feast Deal | F5: 5 | G5: 600 | H5: =F5*G5 -> 3000
E6: Roll & Wrap Special | F6: 4 | G6: 1100 | H6: =F6*G6 -> 4400
E7: Starter Explosion | F7: 4 | G7: 1000 | H7: =F7*G7 -> 4000
E8: Chicken Crunch Deal | F8: 3 | G8: 2200 | H8: =F8*G8 -> 6600
E9: Family Pizza Pack | F9: 3 | G9: 1700 | H9: =F9*G9 -> 5100
E10: Pizza Lover's Delight | F10: 2 | G10: 1800 | H10: =F10*G10 -> 3600
E11: Veggie Feast Deal | F11: 2 | G11: 2200 | H11: =F11*G11 -> 4400
E12: Total Deals | F12: =SUM(F4:F11) -> 28 | H12: =SUM(H4:H11) -> 40100

Sheet Business
B1: FOOD JUNCTION - SALES DASHBOARD
E5: RS 89,550 | F5: 30 | G5: RS 2,985 | H5: COMBO
E6: TOTAL REVENUE | F6: TOTAL ORDERS | G6: AVG ORDER VALUE | H6: TOP CATEGORY
D8: Business
E9: Category | F9: Total Items Sold | G9: Total Revenue (Rs.) | H9: Most Sold Item
E10: Combo Deals | F10: =Burgers!D13 -> 19 | G10: ='Combo Deals'!H12 -> 40100 | H10: The Buger Feast & Urban Feast Deal
E11: Starters | F11: 22 | G11: =Starters!F12 -> 11580 | H11: Hot Wings
E12: Pizzas | F12: =Pizza!F12 -> 10 | G12: =Pizza!H12 -> 10750 | H12: Malai Boti
E13: Burgers | F13: =Burgers!D13 -> 19 | G13: =Burgers!F13 -> 8660 | H13: Zinger Burger
E14: Rolls & Wraps | F14: ='Rolls and Warps'!D10 -> 23 | G14: ='Rolls and Warps'!F10 -> 8350 | H14: Twister Roll
E15: Fries | F15: =Fries!D8 -> 19 | G15: 5590 | H15: Pizza Fries
E16: Light Veg & More | F16: 20 | G16: ='Light Veg'!G8 -> 4520 | H16: Anday Wala Burger
E17: GRAND TOTAL | F17: =SUM(F10:F16) -> 132 | G17: =SUM(G10:G16) -> 89550
